<?xml version="1.0"?>
<robot name="my_robot">

  <link name="base_link"/>

  <link name="upper_arm_link">
    <inertial>
      <origin xyz="0 0 -0.1" rpy="0 0 0"/>
      <mass value="1.0"/>
      <inertia
        ixx="0.01" ixy="0" ixz="0"
        iyy="0.01" iyz="0"
        izz="0.002"/>
    </inertial>

    <visual>
      <origin xyz="0 0 -0.1" rpy="0 0 0"/>
      <geometry>
        <cylinder radius="0.04" length="0.2"/>
      </geometry>
      <material name="arm_color">
        <color rgba="0.7 0.7 0.7 1"/>
      </material>
    </visual>

    <collision>
      <origin xyz="0 0 -0.1" rpy="0 0 0"/>
      <geometry>
        <cylinder radius="0.04" length="0.2"/>
      </geometry>
    </collision>
  </link>

  <joint name="shoulder_joint" type="revolute">
    <parent link="base_link"/>
    <child link="upper_arm_link"/>
    <origin xyz="0 0 0.3" rpy="0 0 0"/>
    <axis xyz="0 1 0"/>
    <limit lower="-1.57"
           upper="1.57"
           effort="20"
           velocity="2"/>
  </joint>

</robot>